<?xml version="1.0" ?>
<!-- =================================================================================== -->
<!-- |    This document was autogenerated by xacro from sia5_with_dhand_and_multi_kinect.urdf.xacro | -->
<!-- |    EDITING THIS FILE BY HAND IS NOT RECOMMENDED                                 | -->
<!-- =================================================================================== -->
<robot name="sia5" xmlns:xacro="http://ros.org/wiki/xacro">
  <!-- File Include -->
  <!-- File Include -->
  <!-- File Include -->
  <material name="black">
    <color rgba="0.0 0.0 0.0 1.0"/>
  </material>
  <material name="blue">
    <color rgba="0.0 0.0 0.8 1.0"/>
  </material>
  <material name="green">
    <color rgba="0.0 0.8 0.0 1.0"/>
  </material>
  <material name="grey">
    <color rgba="0.2 0.2 0.2 1.0"/>
  </material>
  <material name="orange">
    <color rgba="1.0 0.423529411765 0.0392156862745 1.0"/>
  </material>
  <material name="brown">
    <color rgba="0.870588235294 0.811764705882 0.764705882353 1.0"/>
  </material>
  <material name="red">
    <color rgba="0.8 0.0 0.0 1.0"/>
  </material>
  <material name="white">
    <color rgba="1.0 1.0 1.0 1.0"/>
  </material>
  <!-- Mass -->
  <!-- about mass rate -->
  <!-- Hard ware limits -->
  <!-- Range limits -->
  <!-- Velocity limits -->
  <!-- Add macro -->
  <!-- link -->
  <link name="base_link">
    <visual>
      <geometry>
        <mesh filename="package://motoman_description/meshes/sia5/visual/COLLADA/base_link.dae"/>
      </geometry>
    </visual>
    <collision>
      <geometry>
        <mesh filename="package://motoman_description/meshes/sia5/collision/STL/base_link.stl"/>
      </geometry>
    </collision>
    <inertial>
      <origin rpy="0 0 0" xyz="-0.025918 -0.000376 0.076105"/>
      <mass value="9.23913043478"/>
      <inertia ixx="0.0378685009058" ixy="0" ixz="0" iyy="0.0465867830616" iyz="0" izz="0.0514065294384"/>
    </inertial>
  </link>
  <link name="link_s">
    <visual>
      <geometry>
        <mesh filename="package://motoman_description/meshes/sia5/visual/COLLADA/link_s.dae"/>
      </geometry>
    </visual>
    <collision>
      <geometry>
        <mesh filename="package://motoman_description/meshes/sia5/collision/STL/link_s.stl"/>
      </geometry>
    </collision>
    <inertial>
      <origin rpy="0 0 0" xyz="0 0 0"/>
      <mass value="8.36956521739"/>
      <inertia ixx="0.1285284" ixy="0" ixz="0" iyy="0.127697251956" iyz="0" izz="0.0186623672464"/>
    </inertial>
  </link>
  <link name="link_l">
    <visual>
      <geometry>
        <mesh filename="package://motoman_description/meshes/sia5/visual/COLLADA/link_l.dae"/>
      </geometry>
    </visual>
    <collision>
      <geometry>
        <mesh filename="package://motoman_description/meshes/sia5/collision/STL/link_l.stl"/>
      </geometry>
    </collision>
    <inertial>
      <origin rpy="3.14159274 0 0" xyz="0 -0.006 0.15"/>
      <mass value="7.60869565217"/>
      <inertia ixx="0.12248884058" ixy="0" ixz="0" iyy="0.117554616667" iyz="0" izz="0.0177495804348"/>
    </inertial>
  </link>
  <link name="link_e">
    <visual>
      <geometry>
        <mesh filename="package://motoman_description/meshes/sia5/visual/COLLADA/link_e.dae"/>
      </geometry>
    </visual>
    <collision>
      <geometry>
        <mesh filename="package://motoman_description/meshes/sia5/collision/STL/link_e.stl"/>
      </geometry>
    </collision>
    <inertial>
      <origin rpy="0 0 -1.57079637" xyz="0 0 0"/>
      <mass value="1.30434782609"/>
      <inertia ixx="0.0122899381739" ixy="0" ixz="0" iyy="0.0117127787826" iyz="0" izz="0.00344401234783"/>
    </inertial>
  </link>
  <link name="link_u">
    <visual>
      <geometry>
        <mesh filename="package://motoman_description/meshes/sia5/visual/COLLADA/link_u.dae"/>
      </geometry>
    </visual>
    <collision>
      <geometry>
        <mesh filename="package://motoman_description/meshes/sia5/collision/STL/link_u.stl"/>
      </geometry>
    </collision>
    <inertial>
      <origin rpy="-3.14159274 1.57079637 0" xyz="0.008 -0.06 -0.131"/>
      <mass value="1.08695652174"/>
      <inertia ixx="0.0110207115768" ixy="0" ixz="0" iyy="0.00996803594202" iyz="0" izz="0.00214043853333"/>
    </inertial>
  </link>
  <link name="link_r">
    <visual>
      <geometry>
        <mesh filename="package://motoman_description/meshes/sia5/visual/COLLADA/link_r.dae"/>
      </geometry>
    </visual>
    <collision>
      <geometry>
        <mesh filename="package://motoman_description/meshes/sia5/collision/STL/link_r.stl"/>
      </geometry>
    </collision>
    <inertial>
      <origin rpy="0 0 -1.57079637" xyz="0 0 0"/>
      <mass value="0.978260869565"/>
      <inertia ixx="0.0108400832201" ixy="0" ixz="0" iyy="0.010708873981" iyz="0" izz="0.00140456861413"/>
    </inertial>
  </link>
  <link name="link_b">
    <visual>
      <geometry>
        <mesh filename="package://motoman_description/meshes/sia5/visual/COLLADA/link_b.dae"/>
      </geometry>
    </visual>
    <collision>
      <geometry>
        <mesh filename="package://motoman_description/meshes/sia5/collision/STL/link_b.stl"/>
      </geometry>
    </collision>
    <inertial>
      <origin rpy="1.57079637 -1.57079637 0" xyz="0 0.0045 0.1365"/>
      <mass value="0.869565217391"/>
      <inertia ixx="0.00814341869565" ixy="0" ixz="0" iyy="0.00709473869565" iyz="0" izz="0.000736577391304"/>
    </inertial>
  </link>
  <link name="link_t">
    <visual>
      <geometry>
        <mesh filename="package://motoman_description/meshes/sia5/visual/COLLADA/link_t.dae"/>
      </geometry>
    </visual>
    <collision>
      <geometry>
        <mesh filename="package://motoman_description/meshes/sia5/collision/STL/link_t.stl"/>
      </geometry>
    </collision>
    <inertial>
      <mass value="0.54347826087"/>
      <inertia ixx="0.003" ixy="0" ixz="0" iyy="0.003" iyz="0" izz="0.001"/>
    </inertial>
  </link>
  <link name="tool0"/>
  <!-- joint -->
  <joint name="joint_s" type="revolute">
    <origin rpy="0 0 0" xyz="0 0 0.1765"/>
    <parent link="base_link"/>
    <child link="link_s"/>
    <axis xyz="0 0 1"/>
    <dynamics damping="0.7" friction="0.7"/>
    <limit effort="30.0" lower="-2.98451293719" upper="2.98451293719" velocity="3.31612567"/>
  </joint>
  <joint name="joint_l" type="revolute">
    <origin rpy="0 0 0" xyz="0 0.006 0.136"/>
    <parent link="link_s"/>
    <child link="link_l"/>
    <axis xyz="0 1 0"/>
    <dynamics damping="0.7" friction="0.7"/>
    <limit effort="30.0" lower="-1.8238691185" upper="1.8238691185" velocity="3.31612567"/>
  </joint>
  <joint name="joint_e" type="revolute">
    <origin rpy="0 0 0" xyz="0 -0.006 0.15"/>
    <parent link="link_l"/>
    <child link="link_e"/>
    <axis xyz="0 0 1"/>
    <dynamics damping="0.7" friction="0.7"/>
    <limit effort="30.0" lower="-2.8187068195" upper="2.8187068195" velocity="3.31612567"/>
  </joint>
  <joint name="joint_u" type="revolute">
    <origin rpy="1.57079637 0 0" xyz="0.085 -0.00826931 0.12275299"/>
    <parent link="link_e"/>
    <child link="link_u"/>
    <axis xyz="0 0 1"/>
    <dynamics damping="0.7" friction="0.7"/>
    <limit effort="30.0" lower="-1.4922565515" upper="1.90677226025" velocity="3.31612567"/>
  </joint>
  <joint name="joint_r" type="revolute">
    <origin rpy="0 1.57079637 0" xyz="0.131 0.06 -0.008"/>
    <parent link="link_u"/>
    <child link="link_r"/>
    <axis xyz="0 0 -1"/>
    <dynamics damping="0.7" friction="0.7"/>
    <limit effort="14.7" lower="-2.98451293719" upper="2.98451293719" velocity="3.31612567"/>
  </joint>
  <joint name="joint_b" type="revolute">
    <origin rpy="0 -1.57079637 0" xyz="-0.0045 0 0.139"/>
    <parent link="link_r"/>
    <child link="link_b"/>
    <axis xyz="0 0 1"/>
    <dynamics damping="0.7" friction="0.7"/>
    <limit effort="14.7" lower="-1.8238691185" upper="1.8238691185" velocity="3.8135445205"/>
  </joint>
  <joint name="joint_t" type="revolute">
    <origin rpy="-1.57079637 0 0" xyz="0.1365 0 -0.0045"/>
    <parent link="link_b"/>
    <child link="link_t"/>
    <axis xyz="-1 0 0"/>
    <dynamics damping="0.7" friction="0.7"/>
    <limit effort="7.35" lower="-2.98451293719" upper="2.98451293719" velocity="5.8032199225"/>
  </joint>
  <joint name="joint_tool0" type="fixed">
    <origin rpy="0 0 0" xyz="0.0115 0 0"/>
    <parent link="link_t"/>
    <child link="tool0"/>
  </joint>
  <!-- transmission -->
  <transmission name="transmission_s">
    <type>transmission_interface/SimpleTransmission</type>
    <joint name="joint_s">
      <hardwareInterface>PositionJointInterface</hardwareInterface>
    </joint>
    <actuator name="motor_s">
      <hardwareInterface>PositionJointInterface</hardwareInterface>
      <mechanicalReduction>300</mechanicalReduction>
    </actuator>
  </transmission>
  <transmission name="transmission_l">
    <type>transmission_interface/SimpleTransmission</type>
    <joint name="joint_l">
      <hardwareInterface>PositionJointInterface</hardwareInterface>
    </joint>
    <actuator name="motor_l">
      <hardwareInterface>PositionJointInterface</hardwareInterface>
      <mechanicalReduction>300</mechanicalReduction>
    </actuator>
  </transmission>
  <transmission name="transmission_e">
    <type>transmission_interface/SimpleTransmission</type>
    <joint name="joint_e">
      <hardwareInterface>PositionJointInterface</hardwareInterface>
    </joint>
    <actuator name="motor_e">
      <hardwareInterface>PositionJointInterface</hardwareInterface>
      <mechanicalReduction>100</mechanicalReduction>
    </actuator>
  </transmission>
  <transmission name="transmission_u">
    <type>transmission_interface/SimpleTransmission</type>
    <joint name="joint_u">
      <hardwareInterface>PositionJointInterface</hardwareInterface>
    </joint>
    <actuator name="motor_u">
      <hardwareInterface>PositionJointInterface</hardwareInterface>
      <mechanicalReduction>50</mechanicalReduction>
    </actuator>
  </transmission>
  <transmission name="transmission_r">
    <type>transmission_interface/SimpleTransmission</type>
    <joint name="joint_r">
      <hardwareInterface>PositionJointInterface</hardwareInterface>
    </joint>
    <actuator name="motor_r">
      <hardwareInterface>PositionJointInterface</hardwareInterface>
      <mechanicalReduction>30</mechanicalReduction>
    </actuator>
  </transmission>
  <transmission name="transmission_b">
    <type>transmission_interface/SimpleTransmission</type>
    <joint name="joint_b">
      <hardwareInterface>PositionJointInterface</hardwareInterface>
    </joint>
    <actuator name="motor_b">
      <hardwareInterface>PositionJointInterface</hardwareInterface>
      <mechanicalReduction>30</mechanicalReduction>
    </actuator>
  </transmission>
  <transmission name="transmission_t">
    <type>transmission_interface/SimpleTransmission</type>
    <joint name="joint_t">
      <hardwareInterface>PositionJointInterface</hardwareInterface>
    </joint>
    <actuator name="motor_t">
      <hardwareInterface>PositionJointInterface</hardwareInterface>
      <mechanicalReduction>10</mechanicalReduction>
    </actuator>
  </transmission>
  <!-- gazebo -->
  <gazebo>
    <plugin filename="libgazebo_ros_control.so" name="gazebo_ros_control">
      <robotSimType>gazebo_ros_control/DefaultRobotHWSim</robotSimType>
    </plugin>
  </gazebo>
  <gazebo reference="base_link">
    <mu1>0.2</mu1>
    <mu2>0.2</mu2>
    <selfCollide>true</selfCollide>
  </gazebo>
  <gazebo reference="link_s">
    <mu1>0.2</mu1>
    <mu2>0.2</mu2>
    <selfCollide>true</selfCollide>
  </gazebo>
  <gazebo reference="link_l">
    <mu1>0.2</mu1>
    <mu2>0.2</mu2>
    <selfCollide>true</selfCollide>
  </gazebo>
  <gazebo reference="link_e">
    <mu1>0.2</mu1>
    <mu2>0.2</mu2>
    <selfCollide>true</selfCollide>
  </gazebo>
  <gazebo reference="link_u">
    <mu1>0.2</mu1>
    <mu2>0.2</mu2>
    <selfCollide>true</selfCollide>
  </gazebo>
  <gazebo reference="link_r">
    <mu1>0.2</mu1>
    <mu2>0.2</mu2>
    <selfCollide>true</selfCollide>
  </gazebo>
  <gazebo reference="link_b">
    <mu1>0.2</mu1>
    <mu2>0.2</mu2>
    <selfCollide>true</selfCollide>
  </gazebo>
  <gazebo reference="link_t">
    <mu1>0.2</mu1>
    <mu2>0.2</mu2>
    <selfCollide>true</selfCollide>
  </gazebo>
  <!-- =============== Inertial Info =============== -->
  <!-- =============== Link & Joint =============== -->
  <!-- ==== Base ==== -->
  <link name="dhand_base_link">
    <visual>
      <geometry>
        <mesh filename="package://dhand_description/meshes/visual/base/base.dae"/>
      </geometry>
    </visual>
    <collision>
      <geometry>
        <mesh filename="package://dhand_description/meshes/collision/base.STL"/>
      </geometry>
    </collision>
    <inertial>
      <mass value="1.22813391"/>
      <inertia ixx="0.00052834" ixy="0.00000936" ixz="0.00000419" iyy="0.01395061" iyz="0.00000326" izz="0.01395381"/>
    </inertial>
  </link>
  <joint name="dhand_palm_joint" type="fixed">
    <origin xyz="0.255 0 0"/>
    <parent link="dhand_base_link"/>
    <child link="dhand_palm_link"/>
  </joint>
  <link name="dhand_palm_link"/>
  <!-- ==== finger base ==== -->
  <joint name="dhand_finger_base_middle_joint" type="fixed">
    <origin rpy="0 1.57079637 0" xyz="0.1865 0 0.03"/>
    <parent link="dhand_base_link"/>
    <child link="dhand_finger_base_middle_link"/>
  </joint>
  <link name="dhand_finger_base_middle_link">
    <visual>
      <geometry>
        <mesh filename="package://dhand_description/meshes/visual/finger/base/finger_base.dae"/>
      </geometry>
    </visual>
    <collision>
      <geometry>
        <mesh filename="package://dhand_description/meshes/collision/finger/finger_base.STL"/>
      </geometry>
    </collision>
    <inertial>
      <mass value="0.04234931"/>
      <inertia ixx="1e-3" ixy="0.00000000" ixz="-0.00001443" iyy="1e-3" iyz="0.00000000" izz="1e-3"/>
    </inertial>
  </link>
  <joint name="dhand_finger_base_right_joint" type="revolute">
    <origin rpy="3.14159274 -1.57079637 0" xyz="0.1865 -0.025964675 -0.01505875"/>
    <parent link="dhand_base_link"/>
    <child link="dhand_finger_base_right_link"/>
    <axis xyz="0 0 1"/>
    <dynamics damping="0.7" friction="0.7"/>
    <limit effort="10.0" lower="-2.09439516" upper="0.0" velocity="10.0"/>
  </joint>
  <link name="dhand_finger_base_right_link">
    <visual>
      <geometry>
        <mesh filename="package://dhand_description/meshes/visual/finger/base/finger_base.dae"/>
      </geometry>
    </visual>
    <collision>
      <geometry>
        <mesh filename="package://dhand_description/meshes/collision/finger/finger_base.STL"/>
      </geometry>
    </collision>
    <inertial>
      <mass value="0.04234931"/>
      <inertia ixx="1e-3" ixy="0.00000000" ixz="-0.00001443" iyy="1e-3" iyz="0.00000000" izz="1e-3"/>
    </inertial>
  </link>
  <joint name="dhand_finger_base_left_joint" type="revolute">
    <origin rpy="-3.14159274 -1.57079637 0" xyz="0.1865 0.02601464 -0.01494117"/>
    <parent link="dhand_base_link"/>
    <child link="dhand_finger_base_left_link"/>
    <axis xyz="0 0 1"/>
    <dynamics damping="0.7" friction="0.7"/>
    <limit effort="10.0" lower="0.0" upper="2.09439516" velocity="10.0"/>
  </joint>
  <link name="dhand_finger_base_left_link">
    <visual>
      <geometry>
        <mesh filename="package://dhand_description/meshes/visual/finger/base/finger_base.dae"/>
      </geometry>
    </visual>
    <collision>
      <geometry>
        <mesh filename="package://dhand_description/meshes/collision/finger/finger_base.STL"/>
      </geometry>
    </collision>
    <inertial>
      <mass value="0.04234931"/>
      <inertia ixx="1e-3" ixy="0.00000000" ixz="-0.00001443" iyy="1e-3" iyz="0.00000000" izz="1e-3"/>
    </inertial>
  </link>
  <!--==== finger middle ====-->
  <joint name="dhand_finger_middle_middle_joint" type="revolute">
    <origin rpy="1.57079637 0 0" xyz="-0.0415 0 0.033"/>
    <parent link="dhand_finger_base_middle_link"/>
    <child link="dhand_finger_middle_middle_link"/>
    <axis xyz="0 0 -1"/>
    <dynamics damping="0.7" friction="0.7"/>
    <limit effort="10.0" lower="0.0" upper="0.02" velocity="10.0"/>
  </joint>
  <link name="dhand_finger_middle_middle_link">
    <visual>
      <geometry>
        <mesh filename="package://dhand_description/meshes/visual/finger/middle/finger_middle.dae"/>
      </geometry>
    </visual>
    <collision>
      <geometry>
        <mesh filename="package://dhand_description/meshes/collision/finger/finger_middle.STL"/>
      </geometry>
    </collision>
    <inertial>
      <mass value="0.02332939"/>
      <inertia ixx="1e-3" ixy="0.00000220" ixz="0.00000000" iyy="1e-3" iyz="0.00000004" izz="1e-3"/>
    </inertial>
  </link>
  <joint name="dhand_finger_middle_right_joint" type="revolute">
    <origin rpy="1.57079637 0 0" xyz="-0.0415 0 0.033"/>
    <parent link="dhand_finger_base_right_link"/>
    <child link="dhand_finger_middle_right_link"/>
    <axis xyz="0 0 -1"/>
    <dynamics damping="0.7" friction="0.7"/>
    <limit effort="10.0" lower="0.0" upper="0.02" velocity="10.0"/>
  </joint>
  <link name="dhand_finger_middle_right_link">
    <visual>
      <geometry>
        <mesh filename="package://dhand_description/meshes/visual/finger/middle/finger_middle.dae"/>
      </geometry>
    </visual>
    <collision>
      <geometry>
        <mesh filename="package://dhand_description/meshes/collision/finger/finger_middle.STL"/>
      </geometry>
    </collision>
    <inertial>
      <mass value="0.02332939"/>
      <inertia ixx="1e-3" ixy="0.00000220" ixz="0.00000000" iyy="1e-3" iyz="0.00000004" izz="1e-3"/>
    </inertial>
  </link>
  <joint name="dhand_finger_middle_left_joint" type="revolute">
    <origin rpy="1.57079637 0 0" xyz="-0.0415 0 0.033"/>
    <parent link="dhand_finger_base_left_link"/>
    <child link="dhand_finger_middle_left_link"/>
    <axis xyz="0 0 -1"/>
    <dynamics damping="0.7" friction="0.7"/>
    <limit effort="10.0" lower="0.0" upper="0.02" velocity="10.0"/>
  </joint>
  <link name="dhand_finger_middle_left_link">
    <visual>
      <geometry>
        <mesh filename="package://dhand_description/meshes/visual/finger/middle/finger_middle.dae"/>
      </geometry>
    </visual>
    <collision>
      <geometry>
        <mesh filename="package://dhand_description/meshes/collision/finger/finger_middle.STL"/>
      </geometry>
    </collision>
    <inertial>
      <mass value="0.02332939"/>
      <inertia ixx="1e-3" ixy="0.00000220" ixz="0.00000000" iyy="1e-3" iyz="0.00000004" izz="1e-3"/>
    </inertial>
  </link>
  <!-- ==== finger top ==== -->
  <joint name="dhand_finger_top_middle_joint" type="revolute">
    <origin rpy="0 0 0" xyz="0.00976095 0.0434937 0.0"/>
    <parent link="dhand_finger_middle_middle_link"/>
    <child link="dhand_finger_top_middle_link"/>
    <axis xyz="0 0 -1"/>
    <dynamics damping="0.7" friction="0.7"/>
    <limit effort="10.0" lower="0.0" upper="1.40" velocity="10.0"/>
  </joint>
  <link name="dhand_finger_top_middle_link">
    <visual>
      <geometry>
        <mesh filename="package://dhand_description/meshes/visual/finger/top/finger_top.dae"/>
      </geometry>
    </visual>
    <collision>
      <geometry>
        <mesh filename="package://dhand_description/meshes/collision/finger/finger_top.STL"/>
      </geometry>
    </collision>
    <inertial>
      <mass value="0.01452790"/>
      <inertia ixx="1e-3" ixy="0.00000139" ixz="0.00000000" iyy="1e-3" iyz="0.00000000" izz="1e-3"/>
    </inertial>
  </link>
  <joint name="dhand_finger_top_right_joint" type="revolute">
    <origin rpy="0 0 0" xyz="0.00976095 0.0434937 0.0"/>
    <parent link="dhand_finger_middle_right_link"/>
    <child link="dhand_finger_top_right_link"/>
    <axis xyz="0 0 -1"/>
    <dynamics damping="0.7" friction="0.7"/>
    <limit effort="10.0" lower="0.0" upper="1.40" velocity="10.0"/>
  </joint>
  <link name="dhand_finger_top_right_link">
    <visual>
      <geometry>
        <mesh filename="package://dhand_description/meshes/visual/finger/top/finger_top.dae"/>
      </geometry>
    </visual>
    <collision>
      <geometry>
        <mesh filename="package://dhand_description/meshes/collision/finger/finger_top.STL"/>
      </geometry>
    </collision>
    <inertial>
      <mass value="0.01452790"/>
      <inertia ixx="1e-3" ixy="0.00000139" ixz="0.00000000" iyy="1e-3" iyz="0.00000000" izz="1e-3"/>
    </inertial>
  </link>
  <joint name="dhand_finger_top_left_joint" type="revolute">
    <origin rpy="0 0 0" xyz="0.00976095 0.0434937 0.0"/>
    <parent link="dhand_finger_middle_left_link"/>
    <child link="dhand_finger_top_left_link"/>
    <axis xyz="0 0 -1"/>
    <dynamics damping="0.7" friction="0.7"/>
    <limit effort="10.0" lower="0.0" upper="1.40" velocity="10.0"/>
  </joint>
  <link name="dhand_finger_top_left_link">
    <visual>
      <geometry>
        <mesh filename="package://dhand_description/meshes/visual/finger/top/finger_top.dae"/>
      </geometry>
    </visual>
    <collision>
      <geometry>
        <mesh filename="package://dhand_description/meshes/collision/finger/finger_top.STL"/>
      </geometry>
    </collision>
    <inertial>
      <mass value="0.01452790"/>
      <inertia ixx="1e-3" ixy="0.00000139" ixz="0.00000000" iyy="1e-3" iyz="0.00000000" izz="1e-3"/>
    </inertial>
  </link>
  <!-- =============== Gazebo =============== -->
  <!-- ==== Adapter ==== -->
  <gazebo reference="dhand_adapter_link">
    <mu1>0.8</mu1>
    <mu2>0.8</mu2>
    <selfCollide>false</selfCollide>
  </gazebo>
  <!-- ==== Base ==== -->
  <gazebo reference="dhand_base_link">
    <selfCollide>false</selfCollide>
    <mu1 value="0.8"/>
    <mu2 value="0.8"/>
  </gazebo>
  <!-- ==== Fingers ==== -->
  <gazebo reference="dhand_finger_base_middle_link">
    <selfCollide>false</selfCollide>
    <mu1 value="0.8"/>
    <mu2 value="0.8"/>
  </gazebo>
  <gazebo reference="dhand_finger_base_right_link">
    <selfCollide>false</selfCollide>
    <mu1 value="0.8"/>
    <mu2 value="0.8"/>
  </gazebo>
  <gazebo reference="dhand_finger_base_left_link">
    <selfCollide>false</selfCollide>
    <mu1 value="0.8"/>
    <mu2 value="0.8"/>
  </gazebo>
  <gazebo reference="dhand_finger_middle_middle_link">
    <selfCollide>false</selfCollide>
    <mu1 value="0.8"/>
    <mu2 value="0.8"/>
  </gazebo>
  <gazebo reference="dhand_finger_middle_right_link">
    <selfCollide>false</selfCollide>
    <mu1 value="0.8"/>
    <mu2 value="0.8"/>
  </gazebo>
  <gazebo reference="dhand_finger_middle_left_link">
    <selfCollide>false</selfCollide>
    <mu1 value="0.8"/>
    <mu2 value="0.8"/>
  </gazebo>
  <gazebo reference="dhand_finger_top_middle_link">
    <selfCollide>false</selfCollide>
    <mu1 value="0.8"/>
    <mu2 value="0.8"/>
  </gazebo>
  <gazebo reference="dhand_finger_top_right_link">
    <selfCollide>false</selfCollide>
    <mu1 value="0.8"/>
    <mu2 value="0.8"/>
  </gazebo>
  <gazebo reference="dhand_finger_top_left_link">
    <selfCollide>false</selfCollide>
    <mu1 value="0.8"/>
    <mu2 value="0.8"/>
  </gazebo>
  <!-- ====== Transmissions ====== -->
  <transmission name="dhand_finger_base_right_transmission">
    <type>transmission_interface/SimpleTransmission</type>
    <joint name="dhand_finger_base_right_joint">
      <hardwareInterface>PositionJointInterface</hardwareInterface>
    </joint>
    <actuator name="dhand_finger_base_right_motor">
      <hardwareInterface>PositionJointInterface</hardwareInterface>
      <mechanicalReduction>1</mechanicalReduction>
    </actuator>
  </transmission>
  <transmission name="dhand_finger_base_left_transmission">
    <type>transmission_interface/SimpleTransmission</type>
    <joint name="dhand_finger_base_left_joint">
      <hardwareInterface>PositionJointInterface</hardwareInterface>
    </joint>
    <actuator name="dhand_finger_base_left_motor">
      <hardwareInterface>PositionJointInterface</hardwareInterface>
      <mechanicalReduction>1</mechanicalReduction>
    </actuator>
  </transmission>
  <transmission name="dhand_finger_middle_middle_transmission">
    <type>transmission_interface/SimpleTransmission</type>
    <joint name="dhand_finger_middle_middle_joint">
      <hardwareInterface>PositionJointInterface</hardwareInterface>
    </joint>
    <actuator name="dhand_finger_middle_middle_motor">
      <hardwareInterface>PositionJointInterface</hardwareInterface>
      <mechanicalReduction>1</mechanicalReduction>
    </actuator>
  </transmission>
  <transmission name="dhand_finger_middle_right_transmission">
    <type>transmission_interface/SimpleTransmission</type>
    <joint name="dhand_finger_middle_right_joint">
      <hardwareInterface>PositionJointInterface</hardwareInterface>
    </joint>
    <actuator name="dhand_finger_middle_right_motor">
      <hardwareInterface>PositionJointInterface</hardwareInterface>
      <mechanicalReduction>1</mechanicalReduction>
    </actuator>
  </transmission>
  <transmission name="dhand_finger_middle_left_transmission">
    <type>transmission_interface/SimpleTransmission</type>
    <joint name="dhand_finger_middle_left_joint">
      <hardwareInterface>PositionJointInterface</hardwareInterface>
    </joint>
    <actuator name="dhand_finger_middle_left_motor">
      <hardwareInterface>PositionJointInterface</hardwareInterface>
      <mechanicalReduction>1</mechanicalReduction>
    </actuator>
  </transmission>
  <transmission name="dhand_finger_top_middle_transmission">
    <type>transmission_interface/SimpleTransmission</type>
    <joint name="dhand_finger_top_middle_joint">
      <hardwareInterface>PositionJointInterface</hardwareInterface>
    </joint>
    <actuator name="dhand_finger_top_middle_motor">
      <hardwareInterface>PositionJointInterface</hardwareInterface>
      <mechanicalReduction>1</mechanicalReduction>
    </actuator>
  </transmission>
  <transmission name="dhand_finger_top_right_transmission">
    <type>transmission_interface/SimpleTransmission</type>
    <joint name="dhand_finger_top_right_joint">
      <hardwareInterface>PositionJointInterface</hardwareInterface>
    </joint>
    <actuator name="dhand_finger_top_right_motor">
      <hardwareInterface>PositionJointInterface</hardwareInterface>
      <mechanicalReduction>1</mechanicalReduction>
    </actuator>
  </transmission>
  <transmission name="dhand_finger_top_left_transmission">
    <type>transmission_interface/SimpleTransmission</type>
    <joint name="dhand_finger_top_left_joint">
      <hardwareInterface>PositionJointInterface</hardwareInterface>
    </joint>
    <actuator name="dhand_finger_top_left_motor">
      <hardwareInterface>PositionJointInterface</hardwareInterface>
      <mechanicalReduction>1</mechanicalReduction>
    </actuator>
  </transmission>
  <joint name="dhand_base_joint" type="fixed">
    <origin rpy="0 0 0" xyz="0.028 0 0"/>
    <parent link="dhand_adapter_link"/>
    <child link="dhand_base_link"/>
  </joint>
  <link name="dhand_adapter_link">
    <visual>
      <geometry>
        <mesh filename="package://dhand_description/meshes/visual/adapter/adapter.dae"/>
      </geometry>
    </visual>
    <collision>
      <geometry>
        <mesh filename="package://dhand_description/meshes/collision/adapter.STL"/>
      </geometry>
    </collision>
    <inertial>
      <mass value="0.09444833"/>
      <inertia ixx="1e-3" ixy="0.00000000" ixz="0.00000000" iyy="1e-3" iyz="0.00000000" izz="1e-3"/>
    </inertial>
  </link>
  <link name="world"/>
  <joint name="world" type="fixed">
    <origin rpy="0 0 0" xyz="0 0 0.2"/>
    <parent link="world"/>
    <child link="base_link"/>
  </joint>
  <!-- Joint -->
  <joint name="dhand_adapter_joint" type="fixed">
    <origin rpy="3.14159274 0 0" xyz="0 0 0"/>
    <parent link="tool0"/>
    <child link="dhand_adapter_link"/>
  </joint>
  <!-- add Kinect V2 -->
  <!-- Kinect_second -->
  <!-- Link -->
  <link name="kinect_second_link">
    <visual>
      <material name="black"/>
      <geometry>
        <mesh filename="package://motoman_description/meshes/sensor/visual/COLLADA/kinectv2.stl"/>
      </geometry>
    </visual>
    <collision>
      <origin xyz="0 0 0.041"/>
      <geometry>
        <box size="0.065 0.25 0.082"/>
      </geometry>
    </collision>
    <inertial>
      <mass value="0.935"/>
      <inertia ixx="0.0053937" ixy="0" ixz="0" iyy="0.00085311" iyz="0" izz="0.00519899"/>
    </inertial>
  </link>
  <link name="kinect_second_rgb_optical_frame"/>
  <!-- Joint -->
  <joint name="joint_kinect_second" type="fixed">
    <origin rpy="-0.0031 0.4431 3.14" xyz="1.4828 0.0827 0.3932"/>
    <parent link="base_link"/>
    <child link="kinect_second_link"/>
  </joint>
  <joint name="joint_rgb_kinect_second" type="fixed">
    <origin rpy="1.57079637 3.14159274 1.57079637"/>
    <parent link="kinect_second_link"/>
    <child link="kinect_second_rgb_optical_frame"/>
  </joint>
  <!-- Gazebo -->
  <gazebo reference="kinect_second_link">
    <mu1>0.2</mu1>
    <mu2>0.2</mu2>
    <material>Gazebo/Black</material>
    <!-- hd -->
    <sensor name="kinect_second" type="depth">
      <always_on>true</always_on>
      <update_rate>30.0</update_rate>
      <camera>
        <horizontal_fov>1.4678219413</horizontal_fov>
        <image>
          <format>B8G8R8</format>
          <width>512</width>
          <height>424</height>
        </image>
        <clip>
          <near>0.05</near>
          <far>4.5</far>
        </clip>
        <noise>
          <type>gaussian</type>
          <mean>0.0</mean>
          <stddev>0.005</stddev>
        </noise>
      </camera>
      <plugin filename="libgazebo_ros_openni_kinect.so" name="kinect_second_camera_controller">
        <cameraName>kinect_second/hd</cameraName>
        <alwaysOn>true</alwaysOn>
        <updateRate>30</updateRate>
        <imageTopicName>image_color</imageTopicName>
        <depthImageTopicName>image_depth</depthImageTopicName>
        <pointCloudTopicName>points</pointCloudTopicName>
        <cameraInfoTopicName>camera_info</cameraInfoTopicName>
        <depthImageCameraInfoTopicName>camera_info</depthImageCameraInfoTopicName>
        <frameName>kinect_second_rgb_optical_frame</frameName>
        <baseline>0.1</baseline>
        <distortion_k1>0.0</distortion_k1>
        <distortion_k2>0.0</distortion_k2>
        <distortion_k3>0.0</distortion_k3>
        <distortion_t1>0.0</distortion_t1>
        <distortion_t2>0.0</distortion_t2>
        <pointCloudCutoff>0.05</pointCloudCutoff>
        <pointCloudCutoffMax>4.5</pointCloudCutoffMax>
      </plugin>
    </sensor>
    <!-- qhd -->
    <sensor name="kinect_second" type="depth">
      <always_on>true</always_on>
      <update_rate>30.0</update_rate>
      <camera>
        <horizontal_fov>1.4678219413</horizontal_fov>
        <image>
          <format>B8G8R8</format>
          <width>512</width>
          <height>424</height>
        </image>
        <clip>
          <near>0.05</near>
          <far>4.5</far>
        </clip>
        <noise>
          <type>gaussian</type>
          <mean>0.0</mean>
          <stddev>0.005</stddev>
        </noise>
      </camera>
      <plugin filename="libgazebo_ros_openni_kinect.so" name="kinect_second_camera_controller">
        <cameraName>kinect_second/qhd</cameraName>
        <alwaysOn>true</alwaysOn>
        <updateRate>30</updateRate>
        <imageTopicName>image_color</imageTopicName>
        <depthImageTopicName>image_depth</depthImageTopicName>
        <pointCloudTopicName>points</pointCloudTopicName>
        <cameraInfoTopicName>camera_info</cameraInfoTopicName>
        <depthImageCameraInfoTopicName>camera_info</depthImageCameraInfoTopicName>
        <frameName>kinect_second_rgb_optical_frame</frameName>
        <baseline>0.1</baseline>
        <distortion_k1>0.0</distortion_k1>
        <distortion_k2>0.0</distortion_k2>
        <distortion_k3>0.0</distortion_k3>
        <distortion_t1>0.0</distortion_t1>
        <distortion_t2>0.0</distortion_t2>
        <pointCloudCutoff>0.05</pointCloudCutoff>
        <pointCloudCutoffMax>4.5</pointCloudCutoffMax>
      </plugin>
    </sensor>
    <!-- sd -->
    <sensor name="kinect_second" type="depth">
      <always_on>true</always_on>
      <update_rate>30.0</update_rate>
      <camera>
        <horizontal_fov>1.4678219413</horizontal_fov>
        <image>
          <format>B8G8R8</format>
          <width>512</width>
          <height>424</height>
        </image>
        <clip>
          <near>0.05</near>
          <far>4.5</far>
        </clip>
        <noise>
          <type>gaussian</type>
          <mean>0.0</mean>
          <stddev>0.005</stddev>
        </noise>
      </camera>
      <plugin filename="libgazebo_ros_openni_kinect.so" name="kinect_second_camera_controller">
        <cameraName>kinect_second/sd</cameraName>
        <alwaysOn>true</alwaysOn>
        <updateRate>30</updateRate>
        <imageTopicName>image_color</imageTopicName>
        <depthImageTopicName>image_depth</depthImageTopicName>
        <pointCloudTopicName>points</pointCloudTopicName>
        <cameraInfoTopicName>camera_info</cameraInfoTopicName>
        <depthImageCameraInfoTopicName>camera_info</depthImageCameraInfoTopicName>
        <frameName>kinect_second_rgb_optical_frame</frameName>
        <baseline>0.1</baseline>
        <distortion_k1>0.0</distortion_k1>
        <distortion_k2>0.0</distortion_k2>
        <distortion_k3>0.0</distortion_k3>
        <distortion_t1>0.0</distortion_t1>
        <distortion_t2>0.0</distortion_t2>
        <pointCloudCutoff>0.05</pointCloudCutoff>
        <pointCloudCutoffMax>4.5</pointCloudCutoffMax>
      </plugin>
    </sensor>
  </gazebo>
  <!-- Kinect_hand -->
  <!-- Link -->
  <link name="kinect_hand_link">
    <visual>
      <material name="black"/>
      <geometry>
        <mesh filename="package://motoman_description/meshes/sensor/visual/COLLADA/kinectv2.stl"/>
      </geometry>
    </visual>
    <collision>
      <origin xyz="0 0 0.041"/>
      <geometry>
        <box size="0.065 0.25 0.082"/>
      </geometry>
    </collision>
    <inertial>
      <mass value="0.935"/>
      <inertia ixx="0.0053937" ixy="0" ixz="0" iyy="0.00085311" iyz="0" izz="0.00519899"/>
    </inertial>
  </link>
  <link name="kinect_hand_rgb_optical_frame"/>
  <!-- Joint -->
  <joint name="joint_kinect_hand" type="fixed">
    <origin rpy="3.14159274 0 0" xyz="0.09 0 -0.035"/>
    <parent link="link_t"/>
    <child link="kinect_hand_link"/>
  </joint>
  <joint name="joint_rgb_kinect_hand" type="fixed">
    <origin rpy="1.57079637 3.14159274 1.57079637"/>
    <parent link="kinect_hand_link"/>
    <child link="kinect_hand_rgb_optical_frame"/>
  </joint>
  <!-- Gazebo -->
  <gazebo reference="kinect_hand_link">
    <mu1>0.2</mu1>
    <mu2>0.2</mu2>
    <material>Gazebo/Black</material>
    <!-- hd -->
    <sensor name="kinect_hand" type="depth">
      <always_on>true</always_on>
      <update_rate>30.0</update_rate>
      <camera>
        <horizontal_fov>1.4678219413</horizontal_fov>
        <image>
          <format>B8G8R8</format>
          <width>512</width>
          <height>424</height>
        </image>
        <clip>
          <near>0.05</near>
          <far>4.5</far>
        </clip>
        <noise>
          <type>gaussian</type>
          <mean>0.0</mean>
          <stddev>0.005</stddev>
        </noise>
      </camera>
      <plugin filename="libgazebo_ros_openni_kinect.so" name="kinect_hand_camera_controller">
        <cameraName>kinect_hand/hd</cameraName>
        <alwaysOn>true</alwaysOn>
        <updateRate>30</updateRate>
        <imageTopicName>image_color</imageTopicName>
        <depthImageTopicName>image_depth</depthImageTopicName>
        <pointCloudTopicName>points</pointCloudTopicName>
        <cameraInfoTopicName>camera_info</cameraInfoTopicName>
        <depthImageCameraInfoTopicName>camera_info</depthImageCameraInfoTopicName>
        <frameName>kinect_hand_rgb_optical_frame</frameName>
        <baseline>0.1</baseline>
        <distortion_k1>0.0</distortion_k1>
        <distortion_k2>0.0</distortion_k2>
        <distortion_k3>0.0</distortion_k3>
        <distortion_t1>0.0</distortion_t1>
        <distortion_t2>0.0</distortion_t2>
        <pointCloudCutoff>0.05</pointCloudCutoff>
        <pointCloudCutoffMax>4.5</pointCloudCutoffMax>
      </plugin>
    </sensor>
    <!-- qhd -->
    <sensor name="kinect_hand" type="depth">
      <always_on>true</always_on>
      <update_rate>30.0</update_rate>
      <camera>
        <horizontal_fov>1.4678219413</horizontal_fov>
        <image>
          <format>B8G8R8</format>
          <width>512</width>
          <height>424</height>
        </image>
        <clip>
          <near>0.05</near>
          <far>4.5</far>
        </clip>
        <noise>
          <type>gaussian</type>
          <mean>0.0</mean>
          <stddev>0.005</stddev>
        </noise>
      </camera>
      <plugin filename="libgazebo_ros_openni_kinect.so" name="kinect_hand_camera_controller">
        <cameraName>kinect_hand/qhd</cameraName>
        <alwaysOn>true</alwaysOn>
        <updateRate>30</updateRate>
        <imageTopicName>image_color</imageTopicName>
        <depthImageTopicName>image_depth</depthImageTopicName>
        <pointCloudTopicName>points</pointCloudTopicName>
        <cameraInfoTopicName>camera_info</cameraInfoTopicName>
        <depthImageCameraInfoTopicName>camera_info</depthImageCameraInfoTopicName>
        <frameName>kinect_hand_rgb_optical_frame</frameName>
        <baseline>0.1</baseline>
        <distortion_k1>0.0</distortion_k1>
        <distortion_k2>0.0</distortion_k2>
        <distortion_k3>0.0</distortion_k3>
        <distortion_t1>0.0</distortion_t1>
        <distortion_t2>0.0</distortion_t2>
        <pointCloudCutoff>0.05</pointCloudCutoff>
        <pointCloudCutoffMax>4.5</pointCloudCutoffMax>
      </plugin>
    </sensor>
    <!-- sd -->
    <sensor name="kinect_hand" type="depth">
      <always_on>true</always_on>
      <update_rate>30.0</update_rate>
      <camera>
        <horizontal_fov>1.4678219413</horizontal_fov>
        <image>
          <format>B8G8R8</format>
          <width>512</width>
          <height>424</height>
        </image>
        <clip>
          <near>0.05</near>
          <far>4.5</far>
        </clip>
        <noise>
          <type>gaussian</type>
          <mean>0.0</mean>
          <stddev>0.005</stddev>
        </noise>
      </camera>
      <plugin filename="libgazebo_ros_openni_kinect.so" name="kinect_hand_camera_controller">
        <cameraName>kinect_hand/sd</cameraName>
        <alwaysOn>true</alwaysOn>
        <updateRate>30</updateRate>
        <imageTopicName>image_color</imageTopicName>
        <depthImageTopicName>image_depth</depthImageTopicName>
        <pointCloudTopicName>points</pointCloudTopicName>
        <cameraInfoTopicName>camera_info</cameraInfoTopicName>
        <depthImageCameraInfoTopicName>camera_info</depthImageCameraInfoTopicName>
        <frameName>kinect_hand_rgb_optical_frame</frameName>
        <baseline>0.1</baseline>
        <distortion_k1>0.0</distortion_k1>
        <distortion_k2>0.0</distortion_k2>
        <distortion_k3>0.0</distortion_k3>
        <distortion_t1>0.0</distortion_t1>
        <distortion_t2>0.0</distortion_t2>
        <pointCloudCutoff>0.05</pointCloudCutoff>
        <pointCloudCutoffMax>4.5</pointCloudCutoffMax>
      </plugin>
    </sensor>
  </gazebo>
</robot>

