<?xml version="1.0" ?>
<!-- =================================================================================== -->
<!-- |    This document was autogenerated by xacro from sia5_with_jamming.urdf.xacro   | -->
<!-- |    EDITING THIS FILE BY HAND IS NOT RECOMMENDED                                 | -->
<!-- =================================================================================== -->
<robot name="sia5" xmlns:xacro="http://ros.org/wiki/xacro">
  <!-- File Include -->
  <!-- File Include -->
  <material name="black">
    <color rgba="0.0 0.0 0.0 1.0"/>
  </material>
  <material name="blue">
    <color rgba="0.0 0.0 0.8 1.0"/>
  </material>
  <material name="green">
    <color rgba="0.0 0.8 0.0 1.0"/>
  </material>
  <material name="grey">
    <color rgba="0.2 0.2 0.2 1.0"/>
  </material>
  <material name="orange">
    <color rgba="1.0 0.423529411765 0.0392156862745 1.0"/>
  </material>
  <material name="brown">
    <color rgba="0.870588235294 0.811764705882 0.764705882353 1.0"/>
  </material>
  <material name="red">
    <color rgba="0.8 0.0 0.0 1.0"/>
  </material>
  <material name="white">
    <color rgba="1.0 1.0 1.0 1.0"/>
  </material>
  <!-- Mass -->
  <!-- about mass rate -->
  <!-- Hard ware limits -->
  <!-- Range limits -->
  <!-- Velocity limits -->
  <!-- link -->
  <link name="world"/>
  <link name="table_link">
    <visual>
      <geometry>
        <mesh filename="package://motoman_description/meshes/sia5/visual/COLLADA/table_link.dae"/>
      </geometry>
    </visual>
    <collision>
      <origin rpy="0 0 0" xyz="0 0 -0.245"/>
      <geometry>
        <box size="1.116 0.676 0.5"/>
      </geometry>
    </collision>
    <inertial>
      <origin rpy="0 0 0" xyz="0.2 0 0.245"/>
      <mass value="40.0"/>
      <inertia ixx="2.35658666667" ixy="0" ixz="0" iyy="4.98485333333" iyz="0" izz="5.67477333333"/>
    </inertial>
  </link>
  <link name="base_link">
    <visual>
      <geometry>
        <mesh filename="package://motoman_description/meshes/sia5/visual/COLLADA/base_link.dae"/>
      </geometry>
    </visual>
    <collision>
      <geometry>
        <mesh filename="package://motoman_description/meshes/sia5/collision/STL/base_link.stl"/>
      </geometry>
    </collision>
    <inertial>
      <origin rpy="0 0 0" xyz="-0.025918 -0.000376 0.076105"/>
      <mass value="9.23913043478"/>
      <inertia ixx="0.0378685009058" ixy="0" ixz="0" iyy="0.0465867830616" iyz="0" izz="0.0514065294384"/>
    </inertial>
  </link>
  <link name="link_s">
    <visual>
      <geometry>
        <mesh filename="package://motoman_description/meshes/sia5/visual/COLLADA/link_s.dae"/>
      </geometry>
    </visual>
    <collision>
      <geometry>
        <mesh filename="package://motoman_description/meshes/sia5/collision/STL/link_s.stl"/>
      </geometry>
    </collision>
    <inertial>
      <origin rpy="0 0 0" xyz="0 0 0"/>
      <mass value="8.36956521739"/>
      <inertia ixx="0.1285284" ixy="0" ixz="0" iyy="0.127697251956" iyz="0" izz="0.0186623672464"/>
    </inertial>
  </link>
  <link name="link_l">
    <visual>
      <geometry>
        <mesh filename="package://motoman_description/meshes/sia5/visual/COLLADA/link_l.dae"/>
      </geometry>
    </visual>
    <collision>
      <geometry>
        <mesh filename="package://motoman_description/meshes/sia5/collision/STL/link_l.stl"/>
      </geometry>
    </collision>
    <inertial>
      <origin rpy="3.14159274 0 0" xyz="0 -0.006 0.15"/>
      <mass value="7.60869565217"/>
      <inertia ixx="0.12248884058" ixy="0" ixz="0" iyy="0.117554616667" iyz="0" izz="0.0177495804348"/>
    </inertial>
  </link>
  <link name="link_e">
    <visual>
      <geometry>
        <mesh filename="package://motoman_description/meshes/sia5/visual/COLLADA/link_e.dae"/>
      </geometry>
    </visual>
    <collision>
      <geometry>
        <mesh filename="package://motoman_description/meshes/sia5/collision/STL/link_e.stl"/>
      </geometry>
    </collision>
    <inertial>
      <origin rpy="0 0 -1.57079637" xyz="0 0 0"/>
      <mass value="1.30434782609"/>
      <inertia ixx="0.0122899381739" ixy="0" ixz="0" iyy="0.0117127787826" iyz="0" izz="0.00344401234783"/>
    </inertial>
  </link>
  <link name="link_u">
    <visual>
      <geometry>
        <mesh filename="package://motoman_description/meshes/sia5/visual/COLLADA/link_u.dae"/>
      </geometry>
    </visual>
    <collision>
      <geometry>
        <mesh filename="package://motoman_description/meshes/sia5/collision/STL/link_u.stl"/>
      </geometry>
    </collision>
    <inertial>
      <origin rpy="-3.14159274 1.57079637 0" xyz="0.008 -0.06 -0.131"/>
      <mass value="1.08695652174"/>
      <inertia ixx="0.0110207115768" ixy="0" ixz="0" iyy="0.00996803594202" iyz="0" izz="0.00214043853333"/>
    </inertial>
  </link>
  <link name="link_r">
    <visual>
      <geometry>
        <mesh filename="package://motoman_description/meshes/sia5/visual/COLLADA/link_r.dae"/>
      </geometry>
    </visual>
    <collision>
      <geometry>
        <mesh filename="package://motoman_description/meshes/sia5/collision/STL/link_r.stl"/>
      </geometry>
    </collision>
    <inertial>
      <origin rpy="0 0 -1.57079637" xyz="0 0 0"/>
      <mass value="0.978260869565"/>
      <inertia ixx="0.0108400832201" ixy="0" ixz="0" iyy="0.010708873981" iyz="0" izz="0.00140456861413"/>
    </inertial>
  </link>
  <link name="link_b">
    <visual>
      <geometry>
        <mesh filename="package://motoman_description/meshes/sia5/visual/COLLADA/link_b.dae"/>
      </geometry>
    </visual>
    <collision>
      <geometry>
        <mesh filename="package://motoman_description/meshes/sia5/collision/STL/link_b.stl"/>
      </geometry>
    </collision>
    <inertial>
      <origin rpy="1.57079637 -1.57079637 0" xyz="0 0.0045 0.1365"/>
      <mass value="0.869565217391"/>
      <inertia ixx="0.00814341869565" ixy="0" ixz="0" iyy="0.00709473869565" iyz="0" izz="0.000736577391304"/>
    </inertial>
  </link>
  <link name="link_t">
    <visual>
      <geometry>
        <mesh filename="package://motoman_description/meshes/sia5/visual/COLLADA/link_t.dae"/>
      </geometry>
    </visual>
    <collision>
      <geometry>
        <mesh filename="package://motoman_description/meshes/sia5/collision/STL/link_t.stl"/>
      </geometry>
    </collision>
    <inertial>
      <mass value="0.54347826087"/>
      <inertia ixx="0.003" ixy="0" ixz="0" iyy="0.003" iyz="0" izz="0.001"/>
    </inertial>
  </link>
  <link name="tool0"/>
  <!-- joint -->
  <joint name="world" type="fixed">
    <parent link="world"/>
    <child link="table_link"/>
    <origin xyz="0 0 0.51"/>
  </joint>
  <joint name="joint_base" type="fixed">
    <parent link="table_link"/>
    <child link="base_link"/>
  </joint>
  <joint name="joint_s" type="revolute">
    <origin rpy="0 0 0" xyz="0 0 0.1765"/>
    <parent link="base_link"/>
    <child link="link_s"/>
    <axis xyz="0 0 1"/>
    <dynamics damping="0.7" friction="0.7"/>
    <limit effort="30.0" lower="-3.14159256547" upper="3.14159256547" velocity="3.4906586"/>
  </joint>
  <joint name="joint_l" type="revolute">
    <origin rpy="0 0 0" xyz="0 0.006 0.136"/>
    <parent link="link_s"/>
    <child link="link_l"/>
    <axis xyz="0 1 0"/>
    <dynamics damping="0.7" friction="0.7"/>
    <limit effort="30.0" lower="-1.91986223" upper="1.91986223" velocity="3.4906586"/>
  </joint>
  <joint name="joint_e" type="revolute">
    <origin rpy="0 0 0" xyz="0 -0.006 0.15"/>
    <parent link="link_l"/>
    <child link="link_e"/>
    <axis xyz="0 0 1"/>
    <dynamics damping="0.7" friction="0.7"/>
    <limit effort="30.0" lower="-2.96705981" upper="2.96705981" velocity="3.4906586"/>
  </joint>
  <joint name="joint_u" type="revolute">
    <origin rpy="1.57079637 0 0" xyz="0.085 -0.00826931 0.12275299"/>
    <parent link="link_e"/>
    <child link="link_u"/>
    <axis xyz="0 0 1"/>
    <dynamics damping="0.7" friction="0.7"/>
    <limit effort="30.0" lower="-1.57079637" upper="2.007128695" velocity="3.4906586"/>
  </joint>
  <joint name="joint_r" type="revolute">
    <origin rpy="0 1.57079637 0" xyz="0.131 0.06 -0.008"/>
    <parent link="link_u"/>
    <child link="link_r"/>
    <axis xyz="0 0 -1"/>
    <dynamics damping="0.7" friction="0.7"/>
    <limit effort="14.7" lower="-3.14159256547" upper="3.14159256547" velocity="3.4906586"/>
  </joint>
  <joint name="joint_b" type="revolute">
    <origin rpy="0 -1.57079637 0" xyz="-0.0045 0 0.139"/>
    <parent link="link_r"/>
    <child link="link_b"/>
    <axis xyz="0 0 1"/>
    <dynamics damping="0.7" friction="0.7"/>
    <limit effort="14.7" lower="-1.91986223" upper="1.91986223" velocity="4.01425739"/>
  </joint>
  <joint name="joint_t" type="revolute">
    <origin rpy="-1.57079637 0 0" xyz="0.1365 0 -0.0045"/>
    <parent link="link_b"/>
    <child link="link_t"/>
    <axis xyz="-1 0 0"/>
    <dynamics damping="0.7" friction="0.7"/>
    <limit effort="7.35" lower="-3.14159256547" upper="3.14159256547" velocity="6.10865255"/>
  </joint>
  <joint name="joint_tool0" type="fixed">
    <origin rpy="0 0 0" xyz="0.0115 0 0"/>
    <parent link="link_t"/>
    <child link="tool0"/>
  </joint>
  <!-- transmission -->
  <transmission name="transmission_s">
    <type>transmission_interface/SimpleTransmission</type>
    <joint name="joint_s">
      <hardwareInterface>PositionJointInterface</hardwareInterface>
    </joint>
    <actuator name="motor_s">
      <hardwareInterface>PositionJointInterface</hardwareInterface>
      <mechanicalReduction>300</mechanicalReduction>
    </actuator>
  </transmission>
  <transmission name="transmission_l">
    <type>transmission_interface/SimpleTransmission</type>
    <joint name="joint_l">
      <hardwareInterface>PositionJointInterface</hardwareInterface>
    </joint>
    <actuator name="motor_l">
      <hardwareInterface>PositionJointInterface</hardwareInterface>
      <mechanicalReduction>300</mechanicalReduction>
    </actuator>
  </transmission>
  <transmission name="transmission_e">
    <type>transmission_interface/SimpleTransmission</type>
    <joint name="joint_e">
      <hardwareInterface>PositionJointInterface</hardwareInterface>
    </joint>
    <actuator name="motor_e">
      <hardwareInterface>PositionJointInterface</hardwareInterface>
      <mechanicalReduction>100</mechanicalReduction>
    </actuator>
  </transmission>
  <transmission name="transmission_u">
    <type>transmission_interface/SimpleTransmission</type>
    <joint name="joint_u">
      <hardwareInterface>PositionJointInterface</hardwareInterface>
    </joint>
    <actuator name="motor_u">
      <hardwareInterface>PositionJointInterface</hardwareInterface>
      <mechanicalReduction>50</mechanicalReduction>
    </actuator>
  </transmission>
  <transmission name="transmission_r">
    <type>transmission_interface/SimpleTransmission</type>
    <joint name="joint_r">
      <hardwareInterface>PositionJointInterface</hardwareInterface>
    </joint>
    <actuator name="motor_r">
      <hardwareInterface>PositionJointInterface</hardwareInterface>
      <mechanicalReduction>30</mechanicalReduction>
    </actuator>
  </transmission>
  <transmission name="transmission_b">
    <type>transmission_interface/SimpleTransmission</type>
    <joint name="joint_b">
      <hardwareInterface>PositionJointInterface</hardwareInterface>
    </joint>
    <actuator name="motor_b">
      <hardwareInterface>PositionJointInterface</hardwareInterface>
      <mechanicalReduction>30</mechanicalReduction>
    </actuator>
  </transmission>
  <transmission name="transmission_t">
    <type>transmission_interface/SimpleTransmission</type>
    <joint name="joint_t">
      <hardwareInterface>PositionJointInterface</hardwareInterface>
    </joint>
    <actuator name="motor_t">
      <hardwareInterface>PositionJointInterface</hardwareInterface>
      <mechanicalReduction>10</mechanicalReduction>
    </actuator>
  </transmission>
  <!-- gazebo -->
  <gazebo>
    <plugin filename="libgazebo_ros_control.so" name="gazebo_ros_control">
      <robotSimType>gazebo_ros_control/DefaultRobotHWSim</robotSimType>
      <!-- <robotSimType>rosbook_arm_hardware_gazebo/ROSBookArmHardwareGazebo</robotSimType> -->
    </plugin>
  </gazebo>
  <gazebo reference="base_link">
    <mu1>0.2</mu1>
    <mu2>0.2</mu2>
    <selfCollide>true</selfCollide>
  </gazebo>
  <gazebo reference="link_s">
    <mu1>0.2</mu1>
    <mu2>0.2</mu2>
    <selfCollide>true</selfCollide>
  </gazebo>
  <gazebo reference="link_l">
    <mu1>0.2</mu1>
    <mu2>0.2</mu2>
    <selfCollide>true</selfCollide>
  </gazebo>
  <gazebo reference="link_e">
    <mu1>0.2</mu1>
    <mu2>0.2</mu2>
    <selfCollide>true</selfCollide>
  </gazebo>
  <gazebo reference="link_u">
    <mu1>0.2</mu1>
    <mu2>0.2</mu2>
    <selfCollide>true</selfCollide>
  </gazebo>
  <gazebo reference="link_r">
    <mu1>0.2</mu1>
    <mu2>0.2</mu2>
    <selfCollide>true</selfCollide>
  </gazebo>
  <gazebo reference="link_b">
    <mu1>0.2</mu1>
    <mu2>0.2</mu2>
    <selfCollide>true</selfCollide>
  </gazebo>
  <gazebo reference="link_t">
    <mu1>0.2</mu1>
    <mu2>0.2</mu2>
    <selfCollide>true</selfCollide>
  </gazebo>
  <!-- Link -->
  <link name="gripper_link">
    <visual>
      <material name="blue"/>
      <geometry>
        <mesh filename="package://motoman_description/meshes/tool/visual/COLLADA/gripper_link.stl"/>
      </geometry>
    </visual>
    <collision>
      <geometry>
        <mesh filename="package://motoman_description/meshes/tool/collision/STL/gripper_link.stl"/>
      </geometry>
    </collision>
    <inertial>
      <origin rpy="0 0 0" xyz="0 0 0"/>
      <mass value="1.0"/>
      <inertia ixx="0.0337904627083" ixy="0" ixz="0" iyy="0.0337904627083" iyz="0" izz="0.004656125"/>
    </inertial>
  </link>
  <link name="balloon">
    <visual>
      <material name="red"/>
      <geometry>
        <mesh filename="package://motoman_description/meshes/tool/visual/COLLADA/balloon.stl"/>
      </geometry>
    </visual>
    <inertial>
      <mass value="0.3"/>
      <inertia ixx="0.001" ixy="0" ixz="0" iyy="0.001" iyz="0" izz="0.001"/>
    </inertial>
  </link>
  <!-- Joint -->
  <joint name="joint_gripper" type="fixed">
    <origin rpy="-0.1745 0 0" xyz="0.0001 0 0"/>
    <parent link="tool0"/>
    <child link="gripper_link"/>
  </joint>
  <joint name="joint_balloon" type="fixed">
    <origin rpy="0.1745 0 0" xyz="0.108 0 0"/>
    <parent link="gripper_link"/>
    <child link="balloon"/>
  </joint>
  <!-- Gazebo -->
  <gazebo reference="gripper_link">
    <mu1>0.2</mu1>
    <mu2>0.2</mu2>
    <selfCollide>true</selfCollide>
    <material>Gazebo/Blue</material>
  </gazebo>
  <gazebo reference="balloon">
    <mu1>0.2</mu1>
    <mu2>0.2</mu2>
    <selfCollide>true</selfCollide>
    <material>Gazebo/Red</material>
  </gazebo>
</robot>

