<?xml version="1.0" ?>
<!-- =================================================================================== -->
<!-- |    This document was autogenerated by xacro from sda5.urdf.xacro                | -->
<!-- |    EDITING THIS FILE BY HAND IS NOT RECOMMENDED                                 | -->
<!-- =================================================================================== -->
<robot name="sda5" xmlns:xacro="http://ros.org/wiki/xacro">
  <!-- File Include -->
  <!-- File Include -->
  <material name="black">
    <color rgba="0.0 0.0 0.0 1.0"/>
  </material>
  <material name="blue">
    <color rgba="0.0 0.0 0.8 1.0"/>
  </material>
  <material name="green">
    <color rgba="0.0 0.8 0.0 1.0"/>
  </material>
  <material name="grey">
    <color rgba="0.2 0.2 0.2 1.0"/>
  </material>
  <material name="orange">
    <color rgba="1.0 0.423529411765 0.0392156862745 1.0"/>
  </material>
  <material name="brown">
    <color rgba="0.870588235294 0.811764705882 0.764705882353 1.0"/>
  </material>
  <material name="red">
    <color rgba="0.8 0.0 0.0 1.0"/>
  </material>
  <material name="white">
    <color rgba="1.0 1.0 1.0 1.0"/>
  </material>
  <!-- Hard ware limits -->
  <!-- Range limits -->
  <!-- Velocity limits -->
  <!-- Add Macro -->
  <!-- Add Link & Joint -->
  <!-- TORSO Link -->
  <link name="torso_link">
    <visual>
      <geometry>
        <mesh filename="package://motoman_description/meshes/sda5/visual/torso_link/torso_link.dae"/>
      </geometry>
    </visual>
    <collision>
      <geometry>
        <mesh filename="package://motoman_description/meshes/sda5/collision/torso_link.STL"/>
      </geometry>
    </collision>
    <inertial>
      <mass value="30.0"/>
      <inertia ixx="1.12" ixy="0.00" ixz="0.58" iyy="1.47" iyz="0.00" izz="0.49"/>
    </inertial>
  </link>
  <joint name="torso_joint" type="revolute">
    <origin xyz="0.045 0 0.6696"/>
    <parent link="base_link"/>
    <child link="torso_link"/>
    <axis xyz="0 0 1"/>
    <dynamics damping="0.7" friction="0.7"/>
    <limit effort="30.0" lower="-2.96705981" upper="2.96705981" velocity="3.14"/>
  </joint>
  <!-- Link Left Parts -->
  <!-- Link LS -->
  <link name="link_l_s">
    <visual>
      <geometry>
        <mesh filename="package://motoman_description/meshes/sda5/visual/link_s/link_s.dae"/>
      </geometry>
    </visual>
    <collision>
      <geometry>
        <mesh filename="package://motoman_description/meshes/sda5/collision/link_s.STL"/>
      </geometry>
    </collision>
    <inertial>
      <origin rpy="0 0 0" xyz="0 0 0"/>
      <mass value="5.0"/>
      <inertia ixx="0.1285284" ixy="0" ixz="0" iyy="0.127697251956" iyz="0" izz="0.0186623672464"/>
    </inertial>
  </link>
  <joint name="joint_l_s" type="revolute">
    <origin rpy="-1.57079637 0 0" xyz="0.15 0.11225 0.2293"/>
    <parent link="torso_link"/>
    <child link="link_l_s"/>
    <axis xyz="0 0 1"/>
    <dynamics damping="0.7" friction="0.7"/>
    <limit effort="30.0" lower="-1.57079637" upper="4.71238911" velocity="3.49"/>
  </joint>
  <!-- Link LL -->
  <link name="link_l_l">
    <visual>
      <geometry>
        <mesh filename="package://motoman_description/meshes/sda5/visual/link_l/link_l.dae"/>
      </geometry>
    </visual>
    <collision>
      <geometry>
        <mesh filename="package://motoman_description/meshes/sda5/collision/link_l.STL"/>
      </geometry>
    </collision>
    <inertial>
      <origin rpy="3.14159274 0 0" xyz="0 -0.006 0.15"/>
      <mass value="5.0"/>
      <inertia ixx="0.12248884058" ixy="0" ixz="0" iyy="0.117554616667" iyz="0" izz="0.0177495804348"/>
    </inertial>
  </link>
  <joint name="joint_l_l" type="revolute">
    <origin rpy="-1.57079637 0 0" xyz="0 0.03575 0.13"/>
    <parent link="link_l_s"/>
    <child link="link_l_l"/>
    <axis xyz="0 0 1"/>
    <dynamics damping="0.7" friction="0.7"/>
    <limit effort="30.0" lower="-1.91986223" upper="1.91986223" velocity="3.49"/>
  </joint>
  <!-- Link LE -->
  <link name="link_l_e">
    <visual>
      <geometry>
        <mesh filename="package://motoman_description/meshes/sda5/visual/link_e/link_e.dae"/>
      </geometry>
    </visual>
    <collision>
      <geometry>
        <mesh filename="package://motoman_description/meshes/sda5/collision/link_e.STL"/>
      </geometry>
    </collision>
    <inertial>
      <origin rpy="0 0 -1.57079637" xyz="0 0 0"/>
      <mass value="3.0"/>
      <inertia ixx="0.0122899381739" ixy="0" ixz="0" iyy="0.0117127787826" iyz="0" izz="0.00344401234783"/>
    </inertial>
  </link>
  <joint name="joint_l_e" type="revolute">
    <origin rpy="1.57079637 0 0" xyz="0 -0.18225 -0.0365"/>
    <parent link="link_l_l"/>
    <child link="link_l_e"/>
    <axis xyz="0 0 1"/>
    <dynamics damping="0.7" friction="0.7"/>
    <limit effort="30.0" lower="-2.96705981" upper="2.96705981" velocity="3.49"/>
  </joint>
  <!-- Link LU -->
  <link name="link_l_u">
    <visual>
      <geometry>
        <mesh filename="package://motoman_description/meshes/sda5/visual/link_u/link_u.dae"/>
      </geometry>
    </visual>
    <collision>
      <geometry>
        <mesh filename="package://motoman_description/meshes/sda5/collision/link_u.STL"/>
      </geometry>
    </collision>
    <inertial>
      <origin rpy="-3.14159274 1.57079637 0" xyz="0.008 -0.06 -0.131"/>
      <mass value="2.0"/>
      <inertia ixx="0.0110207115768" ixy="0" ixz="0" iyy="0.00996803594202" iyz="0" izz="0.00214043853333"/>
    </inertial>
  </link>
  <joint name="joint_l_u" type="revolute">
    <origin rpy="0 1.57079637 -1.57079637" xyz="0.085 -0.02928 0.087"/>
    <parent link="link_l_e"/>
    <child link="link_l_u"/>
    <axis xyz="0 0 1"/>
    <dynamics damping="0.7" friction="0.7"/>
    <limit effort="30.0" lower="-1.57079637" upper="2.007128695" velocity="3.49"/>
  </joint>
  <!-- Link LR -->
  <link name="link_l_r">
    <visual>
      <geometry>
        <mesh filename="package://motoman_description/meshes/sda5/visual/link_r/link_r.dae"/>
      </geometry>
    </visual>
    <collision>
      <geometry>
        <mesh filename="package://motoman_description/meshes/sda5/collision/link_r.STL"/>
      </geometry>
    </collision>
    <inertial>
      <origin rpy="0 0 -1.57079637" xyz="0 0 0"/>
      <mass value="2.0"/>
      <inertia ixx="0.0108400832201" ixy="0" ixz="0" iyy="0.010708873981" iyz="0" izz="0.00140456861413"/>
    </inertial>
  </link>
  <joint name="joint_l_r" type="revolute">
    <origin rpy="1.57079637 0 0" xyz="-0.06 0.14428 -0.03"/>
    <parent link="link_l_u"/>
    <child link="link_l_r"/>
    <axis xyz="0 0 1"/>
    <dynamics damping="0.7" friction="0.7"/>
    <limit effort="30.0" lower="-3.14159274" upper="3.14159274" velocity="3.49"/>
  </joint>
  <!-- Link LB -->
  <link name="link_l_b">
    <visual>
      <geometry>
        <mesh filename="package://motoman_description/meshes/sda5/visual/link_b/link_b.dae"/>
      </geometry>
    </visual>
    <collision>
      <geometry>
        <mesh filename="package://motoman_description/meshes/sda5/collision/link_b.STL"/>
      </geometry>
    </collision>
    <inertial>
      <origin rpy="1.57079637 -1.57079637 0" xyz="0 0.0045 0.1365"/>
      <mass value="2.0"/>
      <inertia ixx="0.00814341869565" ixy="0" ixz="0" iyy="0.00709473869565" iyz="0" izz="0.000736577391304"/>
    </inertial>
  </link>
  <joint name="joint_l_b" type="revolute">
    <origin rpy="-1.57079637 0 0" xyz="0 -0.0392 -0.125"/>
    <parent link="link_l_r"/>
    <child link="link_l_b"/>
    <axis xyz="0 0 1"/>
    <dynamics damping="0.7" friction="0.7"/>
    <limit effort="30.0" lower="-1.91986223" upper="1.91986223" velocity="4.01"/>
  </joint>
  <!-- Link LT -->
  <link name="link_l_t">
    <visual>
      <geometry>
        <mesh filename="package://motoman_description/meshes/sda5/visual/link_t/link_t.dae"/>
      </geometry>
    </visual>
    <collision>
      <geometry>
        <mesh filename="package://motoman_description/meshes/sda5/collision/link_t.STL"/>
      </geometry>
    </collision>
    <inertial>
      <origin rpy="0 0 0" xyz="0 0 0"/>
      <mass value="1.0"/>
      <inertia ixx="0.003" ixy="0" ixz="0" iyy="0.003" iyz="0" izz="0.001"/>
    </inertial>
  </link>
  <joint name="joint_l_t" type="revolute">
    <origin rpy="1.57079637 0 0" xyz="0 0.1365 0.0392"/>
    <parent link="link_l_b"/>
    <child link="link_l_t"/>
    <axis xyz="0 0 1"/>
    <dynamics damping="0.7" friction="0.7"/>
    <limit effort="30.0" lower="-3.14159274" upper="3.14159274" velocity="6.11"/>
  </joint>
  <!-- Link Right Parts -->
  <!-- Link RS -->
  <link name="link_r_s">
    <visual>
      <geometry>
        <mesh filename="package://motoman_description/meshes/sda5/visual/link_s/link_s.dae"/>
      </geometry>
    </visual>
    <collision>
      <geometry>
        <mesh filename="package://motoman_description/meshes/sda5/collision/link_s.STL"/>
      </geometry>
    </collision>
    <inertial>
      <origin rpy="0 0 0" xyz="0 0 0"/>
      <mass value="5.0"/>
      <inertia ixx="0.1285284" ixy="0" ixz="0" iyy="0.127697251956" iyz="0" izz="0.0186623672464"/>
    </inertial>
  </link>
  <joint name="joint_r_s" type="revolute">
    <origin rpy="1.57079637 0 0" xyz="0.15 -0.11225 0.2293"/>
    <parent link="torso_link"/>
    <child link="link_r_s"/>
    <axis xyz="0 0 1"/>
    <dynamics damping="0.7" friction="0.7"/>
    <limit effort="30.0" lower="-1.57079637" upper="4.71238911" velocity="3.49"/>
  </joint>
  <!-- Link RL -->
  <link name="link_r_l">
    <visual>
      <geometry>
        <mesh filename="package://motoman_description/meshes/sda5/visual/link_l/link_l.dae"/>
      </geometry>
    </visual>
    <collision>
      <geometry>
        <mesh filename="package://motoman_description/meshes/sda5/collision/link_l.STL"/>
      </geometry>
    </collision>
    <inertial>
      <origin rpy="3.14159274 0 0" xyz="0 -0.006 0.15"/>
      <mass value="5.0"/>
      <inertia ixx="0.12248884058" ixy="0" ixz="0" iyy="0.117554616667" iyz="0" izz="0.0177495804348"/>
    </inertial>
  </link>
  <joint name="joint_r_l" type="revolute">
    <origin rpy="-1.57079637 0 0" xyz="0 0.03575 0.13"/>
    <parent link="link_r_s"/>
    <child link="link_r_l"/>
    <axis xyz="0 0 1"/>
    <dynamics damping="0.7" friction="0.7"/>
    <limit effort="30.0" lower="-1.91986223" upper="1.91986223" velocity="3.49"/>
  </joint>
  <!-- Link RE -->
  <link name="link_r_e">
    <visual>
      <geometry>
        <mesh filename="package://motoman_description/meshes/sda5/visual/link_e/link_e.dae"/>
      </geometry>
    </visual>
    <collision>
      <geometry>
        <mesh filename="package://motoman_description/meshes/sda5/collision/link_e.STL"/>
      </geometry>
    </collision>
    <inertial>
      <origin rpy="0 0 -1.57079637" xyz="0 0 0"/>
      <mass value="3.0"/>
      <inertia ixx="0.0122899381739" ixy="0" ixz="0" iyy="0.0117127787826" iyz="0" izz="0.00344401234783"/>
    </inertial>
  </link>
  <joint name="joint_r_e" type="revolute">
    <origin rpy="1.57079637 0 0" xyz="0 -0.18225 -0.0365"/>
    <parent link="link_r_l"/>
    <child link="link_r_e"/>
    <axis xyz="0 0 1"/>
    <dynamics damping="0.7" friction="0.7"/>
    <limit effort="30.0" lower="-2.96705981" upper="2.96705981" velocity="3.49"/>
  </joint>
  <!-- Link RU -->
  <link name="link_r_u">
    <visual>
      <geometry>
        <mesh filename="package://motoman_description/meshes/sda5/visual/link_u/link_u.dae"/>
      </geometry>
    </visual>
    <collision>
      <geometry>
        <mesh filename="package://motoman_description/meshes/sda5/collision/link_u.STL"/>
      </geometry>
    </collision>
    <inertial>
      <origin rpy="-3.14159274 1.57079637 0" xyz="0.008 -0.06 -0.131"/>
      <mass value="2.0"/>
      <inertia ixx="0.0110207115768" ixy="0" ixz="0" iyy="0.00996803594202" iyz="0" izz="0.00214043853333"/>
    </inertial>
  </link>
  <joint name="joint_r_u" type="revolute">
    <origin rpy="0 1.57079637 -1.57079637" xyz="0.085 -0.02928 0.087"/>
    <parent link="link_r_e"/>
    <child link="link_r_u"/>
    <axis xyz="0 0 1"/>
    <dynamics damping="0.7" friction="0.7"/>
    <limit effort="30.0" lower="-1.57079637" upper="2.007128695" velocity="3.49"/>
  </joint>
  <!-- Link RR -->
  <link name="link_r_r">
    <visual>
      <geometry>
        <mesh filename="package://motoman_description/meshes/sda5/visual/link_r/link_r.dae"/>
      </geometry>
    </visual>
    <collision>
      <geometry>
        <mesh filename="package://motoman_description/meshes/sda5/collision/link_r.STL"/>
      </geometry>
    </collision>
    <inertial>
      <origin rpy="0 0 -1.57079637" xyz="0 0 0"/>
      <mass value="2.0"/>
      <inertia ixx="0.0108400832201" ixy="0" ixz="0" iyy="0.010708873981" iyz="0" izz="0.00140456861413"/>
    </inertial>
  </link>
  <joint name="joint_r_r" type="revolute">
    <origin rpy="1.57079637 0 0" xyz="-0.06 0.14428 -0.03"/>
    <parent link="link_r_u"/>
    <child link="link_r_r"/>
    <axis xyz="0 0 1"/>
    <dynamics damping="0.7" friction="0.7"/>
    <limit effort="30.0" lower="-3.14159274" upper="3.14159274" velocity="3.49"/>
  </joint>
  <!-- Link RB -->
  <link name="link_r_b">
    <visual>
      <geometry>
        <mesh filename="package://motoman_description/meshes/sda5/visual/link_b/link_b.dae"/>
      </geometry>
    </visual>
    <collision>
      <geometry>
        <mesh filename="package://motoman_description/meshes/sda5/collision/link_b.STL"/>
      </geometry>
    </collision>
    <inertial>
      <origin rpy="1.57079637 -1.57079637 0" xyz="0 0.0045 0.1365"/>
      <mass value="2.0"/>
      <inertia ixx="0.00814341869565" ixy="0" ixz="0" iyy="0.00709473869565" iyz="0" izz="0.000736577391304"/>
    </inertial>
  </link>
  <joint name="joint_r_b" type="revolute">
    <origin rpy="-1.57079637 0 0" xyz="0 -0.0392 -0.125"/>
    <parent link="link_r_r"/>
    <child link="link_r_b"/>
    <axis xyz="0 0 1"/>
    <dynamics damping="0.7" friction="0.7"/>
    <limit effort="30.0" lower="-1.91986223" upper="1.91986223" velocity="4.01"/>
  </joint>
  <!-- Link RT -->
  <link name="link_r_t">
    <visual>
      <geometry>
        <mesh filename="package://motoman_description/meshes/sda5/visual/link_t/link_t.dae"/>
      </geometry>
    </visual>
    <collision>
      <geometry>
        <mesh filename="package://motoman_description/meshes/sda5/collision/link_t.STL"/>
      </geometry>
    </collision>
    <inertial>
      <origin rpy="0 0 0" xyz="0 0 0"/>
      <mass value="1.0"/>
      <inertia ixx="0.003" ixy="0" ixz="0" iyy="0.003" iyz="0" izz="0.001"/>
    </inertial>
  </link>
  <joint name="joint_r_t" type="revolute">
    <origin rpy="1.57079637 0 0" xyz="0 0.1365 0.0392"/>
    <parent link="link_r_b"/>
    <child link="link_r_t"/>
    <axis xyz="0 0 1"/>
    <dynamics damping="0.7" friction="0.7"/>
    <limit effort="30.0" lower="-3.14159274" upper="3.14159274" velocity="6.11"/>
  </joint>
  <!-- Add Transmission -->
  <transmission name="trans_torso">
    <type>transmission_interface/SimpleTransmission</type>
    <joint name="torso_joint">
      <hardwareInterface>PositionJointInterface</hardwareInterface>
    </joint>
    <actuator name="torso_actuator">
      <hardwareInterface>PositionJointInterface</hardwareInterface>
      <mechanicalReduction>300</mechanicalReduction>
    </actuator>
  </transmission>
  <transmission name="trans_l_s">
    <type>transmission_interface/SimpleTransmission</type>
    <joint name="joint_l_s">
      <hardwareInterface>PositionJointInterface</hardwareInterface>
    </joint>
    <actuator name="actuator_l_s">
      <hardwareInterface>PositionJointInterface</hardwareInterface>
      <mechanicalReduction>300</mechanicalReduction>
    </actuator>
  </transmission>
  <transmission name="trans_l_l">
    <type>transmission_interface/SimpleTransmission</type>
    <joint name="joint_l_l">
      <hardwareInterface>PositionJointInterface</hardwareInterface>
    </joint>
    <actuator name="actuator_l_l">
      <hardwareInterface>PositionJointInterface</hardwareInterface>
      <mechanicalReduction>300</mechanicalReduction>
    </actuator>
  </transmission>
  <transmission name="trans_l_e">
    <type>transmission_interface/SimpleTransmission</type>
    <joint name="joint_l_e">
      <hardwareInterface>PositionJointInterface</hardwareInterface>
    </joint>
    <actuator name="actuator_l_e">
      <hardwareInterface>PositionJointInterface</hardwareInterface>
      <mechanicalReduction>100</mechanicalReduction>
    </actuator>
  </transmission>
  <transmission name="trans_l_u">
    <type>transmission_interface/SimpleTransmission</type>
    <joint name="joint_l_u">
      <hardwareInterface>PositionJointInterface</hardwareInterface>
    </joint>
    <actuator name="actuator_l_u">
      <hardwareInterface>PositionJointInterface</hardwareInterface>
      <mechanicalReduction>50</mechanicalReduction>
    </actuator>
  </transmission>
  <transmission name="trans_l_r">
    <type>transmission_interface/SimpleTransmission</type>
    <joint name="joint_l_r">
      <hardwareInterface>PositionJointInterface</hardwareInterface>
    </joint>
    <actuator name="actuator_l_r">
      <hardwareInterface>PositionJointInterface</hardwareInterface>
      <mechanicalReduction>30</mechanicalReduction>
    </actuator>
  </transmission>
  <transmission name="trans_l_b">
    <type>transmission_interface/SimpleTransmission</type>
    <joint name="joint_l_b">
      <hardwareInterface>PositionJointInterface</hardwareInterface>
    </joint>
    <actuator name="actuator_l_b">
      <hardwareInterface>PositionJointInterface</hardwareInterface>
      <mechanicalReduction>30</mechanicalReduction>
    </actuator>
  </transmission>
  <transmission name="trans_l_t">
    <type>transmission_interface/SimpleTransmission</type>
    <joint name="joint_l_t">
      <hardwareInterface>PositionJointInterface</hardwareInterface>
    </joint>
    <actuator name="actuator_l_t">
      <hardwareInterface>PositionJointInterface</hardwareInterface>
      <mechanicalReduction>10</mechanicalReduction>
    </actuator>
  </transmission>
  <transmission name="trans_r_s">
    <type>transmission_interface/SimpleTransmission</type>
    <joint name="joint_r_s">
      <hardwareInterface>PositionJointInterface</hardwareInterface>
    </joint>
    <actuator name="actuator_r_s">
      <hardwareInterface>PositionJointInterface</hardwareInterface>
      <mechanicalReduction>300</mechanicalReduction>
    </actuator>
  </transmission>
  <transmission name="trans_r_l">
    <type>transmission_interface/SimpleTransmission</type>
    <joint name="joint_r_l">
      <hardwareInterface>PositionJointInterface</hardwareInterface>
    </joint>
    <actuator name="actuator_r_l">
      <hardwareInterface>PositionJointInterface</hardwareInterface>
      <mechanicalReduction>300</mechanicalReduction>
    </actuator>
  </transmission>
  <transmission name="trans_r_e">
    <type>transmission_interface/SimpleTransmission</type>
    <joint name="joint_r_e">
      <hardwareInterface>PositionJointInterface</hardwareInterface>
    </joint>
    <actuator name="actuator_r_e">
      <hardwareInterface>PositionJointInterface</hardwareInterface>
      <mechanicalReduction>100</mechanicalReduction>
    </actuator>
  </transmission>
  <transmission name="trans_r_u">
    <type>transmission_interface/SimpleTransmission</type>
    <joint name="joint_r_u">
      <hardwareInterface>PositionJointInterface</hardwareInterface>
    </joint>
    <actuator name="actuator_r_u">
      <hardwareInterface>PositionJointInterface</hardwareInterface>
      <mechanicalReduction>50</mechanicalReduction>
    </actuator>
  </transmission>
  <transmission name="trans_r_r">
    <type>transmission_interface/SimpleTransmission</type>
    <joint name="joint_r_r">
      <hardwareInterface>PositionJointInterface</hardwareInterface>
    </joint>
    <actuator name="actuator_r_r">
      <hardwareInterface>PositionJointInterface</hardwareInterface>
      <mechanicalReduction>30</mechanicalReduction>
    </actuator>
  </transmission>
  <transmission name="trans_r_b">
    <type>transmission_interface/SimpleTransmission</type>
    <joint name="joint_r_b">
      <hardwareInterface>PositionJointInterface</hardwareInterface>
    </joint>
    <actuator name="actuator_r_b">
      <hardwareInterface>PositionJointInterface</hardwareInterface>
      <mechanicalReduction>30</mechanicalReduction>
    </actuator>
  </transmission>
  <transmission name="trans_r_t">
    <type>transmission_interface/SimpleTransmission</type>
    <joint name="joint_r_t">
      <hardwareInterface>PositionJointInterface</hardwareInterface>
    </joint>
    <actuator name="actuator_r_t">
      <hardwareInterface>PositionJointInterface</hardwareInterface>
      <mechanicalReduction>10</mechanicalReduction>
    </actuator>
  </transmission>
  <!-- Add Gazebo -->
  <gazebo reference="torso_link">
    <mu1>0.2</mu1>
    <mu2>0.2</mu2>
    <selfCollide>true</selfCollide>
  </gazebo>
  <gazebo reference="link_l_s">
    <mu1>0.2</mu1>
    <mu2>0.2</mu2>
    <selfCollide>true</selfCollide>
  </gazebo>
  <gazebo reference="link_l_l">
    <mu1>0.2</mu1>
    <mu2>0.2</mu2>
    <selfCollide>true</selfCollide>
  </gazebo>
  <gazebo reference="link_l_e">
    <mu1>0.2</mu1>
    <mu2>0.2</mu2>
    <selfCollide>true</selfCollide>
  </gazebo>
  <gazebo reference="link_l_u">
    <mu1>0.2</mu1>
    <mu2>0.2</mu2>
    <selfCollide>true</selfCollide>
  </gazebo>
  <gazebo reference="link_l_r">
    <mu1>0.2</mu1>
    <mu2>0.2</mu2>
    <selfCollide>true</selfCollide>
  </gazebo>
  <gazebo reference="link_l_b">
    <mu1>0.2</mu1>
    <mu2>0.2</mu2>
    <selfCollide>true</selfCollide>
  </gazebo>
  <gazebo reference="link_l_t">
    <mu1>0.2</mu1>
    <mu2>0.2</mu2>
    <selfCollide>true</selfCollide>
  </gazebo>
  <gazebo reference="link_r_s">
    <mu1>0.2</mu1>
    <mu2>0.2</mu2>
    <selfCollide>true</selfCollide>
  </gazebo>
  <gazebo reference="link_r_l">
    <mu1>0.2</mu1>
    <mu2>0.2</mu2>
    <selfCollide>true</selfCollide>
  </gazebo>
  <gazebo reference="link_r_e">
    <mu1>0.2</mu1>
    <mu2>0.2</mu2>
    <selfCollide>true</selfCollide>
  </gazebo>
  <gazebo reference="link_r_u">
    <mu1>0.2</mu1>
    <mu2>0.2</mu2>
    <selfCollide>true</selfCollide>
  </gazebo>
  <gazebo reference="link_r_r">
    <mu1>0.2</mu1>
    <mu2>0.2</mu2>
    <selfCollide>true</selfCollide>
  </gazebo>
  <gazebo reference="link_r_b">
    <mu1>0.2</mu1>
    <mu2>0.2</mu2>
    <selfCollide>true</selfCollide>
  </gazebo>
  <gazebo reference="link_r_t">
    <mu1>0.2</mu1>
    <mu2>0.2</mu2>
    <selfCollide>true</selfCollide>
  </gazebo>
  <!-- Add Gazebo plugin -->
  <gazebo>
    <plugin filename="libgazebo_ros_control.so" name="gazebo_ros_control">
      <robotSimType>gazebo_ros_control/DefaultRobotHWSim</robotSimType>
    </plugin>
  </gazebo>
  <link name="world"/>
  <link name="base_link">
    <visual>
      <geometry>
        <mesh filename="package://motoman_description/meshes/sda5/visual/base_link/base_link.dae"/>
      </geometry>
    </visual>
    <collision>
      <geometry>
        <mesh filename="package://motoman_description/meshes/sda5/collision/base_link.STL"/>
      </geometry>
    </collision>
    <inertial>
      <mass value="40.0"/>
      <inertia ixx="5.28" ixy="0.00" ixz="0.47" iyy="5.30" iyz="0.00" izz="0.28"/>
    </inertial>
  </link>
  <joint name="base_joint" type="fixed">
    <origin rpy="0 0 0" xyz="0 0 0"/>
    <parent link="world"/>
    <child link="base_link"/>
  </joint>
</robot>

